<?xml version="1.0" ?>
<robot name="irb120" xmlns:xacro="http://ros.org/wiki/xacro">

    <!-- Create materials -->
    <material name="blue">
        <color rgba="0.8 0.8 0.8 1.0"/>
    </material>

    <material name="yellow">
        <color rgba="0.2 0.2 0.2 1.0"/>
    </material>
         
    <!-- Link list -->
    <link name="base_link">
        <visual>
            <origin rpy="0 0 0" xyz="0 0 0"/>
            <geometry>
                <mesh filename="package://irb120/irb120/visual/base_link.stl"/>
            </geometry>
            <material name="blue"/>
        </visual>
        <collision>
            <origin rpy="0 0 0" xyz="0 0 0"/>
            <geometry>
                <mesh filename="package://irb120/irb120/collision/base_link.stl"/>
            </geometry>
        </collision>
        <inertial>
            <mass value="6.21503193527"/>
            <inertia ixx="0.0247272" ixy="-8.0784e-05" ixz="0.00130902" iyy="0.0491285" iyz="-8.0419e-06" izz="0.0472376"/>
            <origin rpy="0 0 0" xyz="-0.04204 8.01e-05 0.07964"/>
        </inertial>      
    </link>
         
    <link name="link_1">
        <visual>
            <origin rpy="0 0 0" xyz="0 0 0"/>
            <geometry>
                <mesh filename="package://irb120/irb120/visual/link_1.stl"/>
            </geometry>
            <material name="blue"/>
        </visual>
        <collision>
            <origin rpy="0 0 0" xyz="0 0 0"/>
            <geometry>
                <mesh filename="package://irb120/irb120/collision/link_1.stl"/>
            </geometry>
        </collision>
        <inertial>
            <mass value="3.06736850696"/>
            <inertia ixx="0.0142175" ixy="-1.28579e-05" ixz="-2.31364e-05" iyy="0.0144041" iyz="1.93404e-05" izz="0.0104533"/>
            <origin rpy="0 0 0" xyz="9.77e-05 -0.00012 0.23841"/>
        </inertial>      
    </link>

    <link name="link_2">
        <visual>
            <origin rpy="0 0 0" xyz="0 0 0"/>
            <geometry>
                <mesh filename="package://irb120/irb120/visual/link_2.stl"/>
            </geometry>
            <material name="blue"/>
        </visual>
        <collision>
            <origin rpy="0 0 0" xyz="0 0 0"/>
            <geometry>
                <mesh filename="package://irb120/irb120/collision/link_2.stl"/>
            </geometry>
            <material name="blue"/>
        </collision>
        <inertial>
            <mass value="3.90875060185"/>
            <inertia ixx="0.0603111" ixy="9.83431e-06" ixz="5.72407e-05" iyy="0.041569" iyz="-0.00050497" izz="0.0259548"/>
            <origin rpy="0 0 0" xyz="0.00078 -0.00212 0.10124"/>
        </inertial>      
    </link>
         
    <link name="link_3">
        <visual>
            <origin rpy="0 0 0" xyz="0 0 0"/>
            <geometry>
                <mesh filename="package://irb120/irb120/visual/link_3.stl"/>
            </geometry>
            <material name="blue"/>
        </visual>
        <collision>
            <origin rpy="0 0 0" xyz="0 0 0"/>
            <geometry>
                <mesh filename="package://irb120/irb120/collision/link_3.stl"/>
            </geometry>
            <material name="blue"/>
        </collision>
        <inertial>
            <mass value="2.94383262499"/>
            <inertia ixx="0.00835606" ixy="-8.01545e-05" ixz="0.00142884" iyy="0.016713" iyz="-0.000182227" izz="0.0126984"/>
            <origin rpy="0 0 0" xyz="0.02281 0.00106 0.05791"/>
        </inertial>      
    </link>
         
         
    <link name="link_4">
        <visual>
            <origin rpy="0 0 0" xyz="0 0 0"/>
            <geometry>
                <mesh filename="package://irb120/irb120/visual/link_4.stl"/>
            </geometry>
        </visual>
        <collision>
            <origin rpy="0 0 0" xyz="0 0 0"/>
            <geometry>
                <mesh filename="package://irb120/irb120/collision/link_4.stl"/>
            </geometry>
        </collision>
        <inertial>
            <mass value="1.32790527095"/>
            <inertia ixx="0.00284661" ixy="-2.12765e-05" ixz="-1.6435e-05" iyy="0.00401346" iyz="1.31336e-05" izz="0.0052535"/>
            <origin rpy="0 0 0" xyz="0.2247 0.00015 0.00041"/> 
            </inertial>    
    </link>
         
    <link name="link_5">
        <visual>
            <origin rpy="0 0 0" xyz="0 0 0"/>
            <geometry>
                <mesh filename="package://irb120/irb120/visual/link_5.stl"/>
            </geometry>
        </visual>
        <collision>
            <origin rpy="0 0 0" xyz="0 0 0"/>
            <geometry>
                <mesh filename="package://irb120/irb120/collision/link_5.stl"/>
            </geometry>
        </collision>
        <inertial>
            <mass value="0.546633236934"/>
            <inertia ixx="0.000404891" ixy="1.61943e-06" ixz="8.46805e-07" iyy="0.000892825" iyz="-1.51792e-08" izz="0.000815468"/>
            <origin rpy="0 0 0" xyz="-0.00109 3.68e-05 6.22e-05"/>
        </inertial>    
    </link>
         
    <link name="link_6">
        <visual>
            <origin rpy="0 0 0" xyz="0 0 0"/>
            <geometry>
                <mesh filename="package://irb120/irb120/visual/link_6.stl"/>
            </geometry>
        </visual>
        <collision>
            <origin rpy="0 0 0" xyz="0 0 0"/>
            <geometry>
                <mesh filename="package://irb120/irb120/collision/link_6.stl"/>
            </geometry>
        </collision>
        <inertial>
            <mass value="0.0136784407912"/>
            <!--<inertia ixx="1.65768910842e-06" ixy="-3.0670406059e-12" ixz="8.9225606574e-11" iyy="1.69424824883e-06" iyz="-7.6624364717e-09" izz="2.9767913551e-06"/>-->
            <!--<origin rpy="0 0 0" xyz="-4.42649390919e-07 0.000169444143624 -0.0070610831163"/>-->
            <inertia ixx="0.001" ixy="0" ixz="0" iyy="0.001" iyz="0" izz="0.001"/>
            <origin rpy="0 0 0" xyz="-0.00706 -0.00017 -1.32e-06"/>
        </inertial>    
    </link>

    <!-- End link list -->
         
    <!-- Joint list -->
    <joint name="joint_1" type="revolute">
        <origin rpy="0 0 0" xyz="0 0 0"/>
        <parent link="base_link"/>
        <child link="link_1"/>
           <limit effort="20" lower="-2.87979326579" upper="2.87979326579" velocity="4.36332312999"/>
        <axis xyz="0 0 1"/>
        <dynamics damping="0.0" friction="0.0"/>
    </joint>
         
    <joint name="joint_2" type="revolute">
        <origin rpy="0 0 0" xyz="0 0 0.29"/>
        <parent link="link_1"/>
        <child link="link_2"/>
             <limit effort="20" lower="-1.91986217719" upper="1.91986217719" velocity="4.36332312999"/>
        <axis xyz="0 1 0"/>
        <dynamics damping="0.0" friction="0.0"/>
    </joint>
         
    <joint name="joint_3" type="revolute">
        <origin rpy="0 0 0" xyz="0 0 0.27"/>
        <parent link="link_2"/>
        <child link="link_3"/>
             <limit effort="20" lower="-1.91986217719" upper="1.22173047639" velocity="4.36332312999"/>
        <axis xyz="0 1 0"/>
        <dynamics damping="0.0" friction="0.0"/>
    </joint>
         
    <joint name="joint_4" type="revolute">
        <origin rpy="0 0 0" xyz="0 0 0.07"/>
        <parent link="link_3"/>
        <child link="link_4"/>
           <limit effort="20" lower="-2.79252680319" upper="2.79252680319" velocity="5.58505360639"/>
        <axis xyz="1 0 0"/>
        <dynamics damping="0.0" friction="0.0"/>
    </joint>

    <joint name="joint_5" type="revolute">
        <origin rpy="0 0 0" xyz="0.302 0 0"/>
        <parent link="link_4"/>
        <child link="link_5"/>
            <limit effort="20" lower="-2.09439510239" upper="2.09439510239" velocity="5.58505360639"/>
        <axis xyz="0 1 0"/>
        <dynamics damping="0.0" friction="0.0"/>
    </joint>
         
    <joint name="joint_6" type="revolute">
        <origin rpy="0 0 0" xyz="0.072 0 0"/>
        <parent link="link_5"/>
        <child link="link_6"/>
          <limit effort="20" lower="-3.0" upper="3.0" velocity="7.33038285839"/>
        <!--<limit effort="1" lower="-2.981317008" upper="2.981317008" velocity="7.33038285839"/>-->
        <!--<limit effort="1" lower="-6.981317008" upper="6.981317008" velocity="7.33038285839"/>-->
        <axis xyz="1 0 0"/>
        <dynamics damping="0.0" friction="0.0"/>
    </joint>
         


 <joint name="ee_fixed_joint" type="fixed">
    <parent link="link_6"/>
    <child link="ee_link"/>
    <origin rpy=" 0.0 0 0.0" xyz="0.0 0.0823 0.0"/>
  </joint>
  <link name="ee_link">
    <!-- <collision>
      <geometry>
        <box size="0.01 0.01 0.01"/>
      </geometry>
      <origin rpy="0 1.57079632679 0" xyz="0 -0.08 0"/>
    </collision> -->
    <inertial>
      <mass value="0.0"/>
      <origin rpy="0 0 0" xyz="0.0 0.0 0.0"/>
      <inertia ixx="0.0" ixy="0.0" ixz="0.0" iyy="0.0" iyz="0.0" izz="0.0"/>
    </inertial>
  </link>

  <link name="tool0">
    <inertial>
      <mass value="0.0"/>
      <origin rpy="0 0 0" xyz="0.0 0 0.0"/>
      <inertia ixx="0.0" ixy="0.0" ixz="0.0" iyy="0.0" iyz="0.0" izz="0.0"/>
    </inertial>
  </link>
  <joint name="link_6-tool0_fixed_joint" type="fixed">
    <origin rpy="0 1.57079632679 0" xyz="0 0 0"/>
    <parent link="link_6"/>
    <child link="tool0"/>
  </joint>
  <joint name="tool0-tool_tip" type="fixed">
    <origin rpy="0 0 0" xyz="0 0 0.12"/>
    <parent link="tool0"/>
    <child link="tool_tip"/>
  </joint>
  <link name="tool_tip">
    <inertial>
      <mass value="0.0"/>
      <origin rpy="0 0 0" xyz="0.0 0.0 0.0"/>
      <inertia ixx="0.0" ixy="0.0" ixz="0.0" iyy="0.0" iyz="0.0" izz="0.0"/>
    </inertial>
    <!-- <visual>
      <geometry>
        <box size="0.01 0.01 0.01"/>
      </geometry>
      <origin rpy="0 0 0" xyz="0 0 0"/>
    </visual> -->
  </link>


 <link name="world"/>
  <joint name="world_joint" type="fixed">
    <parent link="world"/>
    <child link="base_link"/>
    <origin rpy="0.0 0.0 0.0" xyz="0.0 0.0 0.0"/>
  </joint>



    <!-- End joint list -->
    
    <!-- Transmission list -->

    <transmission name="tran_1">
        <type>transmission_interface/SimpleTransmission</type>
        <joint name="joint_1">
            <hardwareInterface>hardware_interface/PositionJointInterface</hardwareInterface>
        </joint>
        <actuator name="motor_1">
            <hardwareInterface>hardware_interface/PositionJointInterface</hardwareInterface>
            <mechanicalReduction>1</mechanicalReduction>
        </actuator>
    </transmission>
    <transmission name="tran_2">
        <type>transmission_interface/SimpleTransmission</type>
        <joint name="joint_2">
            <hardwareInterface>hardware_interface/PositionJointInterface</hardwareInterface>
        </joint>
        <actuator name="motor_2">
            <hardwareInterface>hardware_interface/PositionJointInterface</hardwareInterface>
            <mechanicalReduction>1</mechanicalReduction>
            <hardwareInterface>hardware_interface/PositionJointInterface</hardwareInterface>
        </actuator>
    </transmission>
    <transmission name="tran_3">
        <type>transmission_interface/SimpleTransmission</type>
        <joint name="joint_3">
            <hardwareInterface>hardware_interface/PositionJointInterface</hardwareInterface>
        </joint>
        <actuator name="motor_3">
            <hardwareInterface>hardware_interface/PositionJointInterface</hardwareInterface>
            <mechanicalReduction>1</mechanicalReduction>
        </actuator>
    </transmission>
    <transmission name="tran_4">
        <type>transmission_interface/SimpleTransmission</type>
        <joint name="joint_4">
            <hardwareInterface>hardware_interface/PositionJointInterface</hardwareInterface>
        </joint>
        <actuator name="motor_4">
            <mechanicalReduction>1</mechanicalReduction>
        </actuator>
    </transmission>
    <transmission name="tran_5">
        <type>transmission_interface/SimpleTransmission</type>
        <joint name="joint_5">
            <hardwareInterface>hardware_interface/PositionJointInterface</hardwareInterface>
        </joint>
        <actuator name="motor_5">
            <hardwareInterface>hardware_interface/PositionJointInterface</hardwareInterface>
            <mechanicalReduction>1</mechanicalReduction>
        </actuator>
    </transmission>
    <transmission name="tran_6">
        <type>transmission_interface/SimpleTransmission</type>
        <joint name="joint_6">
            <hardwareInterface>hardware_interface/PositionJointInterface</hardwareInterface>
        </joint>
        <actuator name="motor_6">
            <hardwareInterface>hardware_interface/PositionJointInterface</hardwareInterface>
            <mechanicalReduction>1</mechanicalReduction>
        </actuator>
    </transmission>

    <!-- End transmission list -->

    <!-- Gazebo specific link properties for color and gravity-->
    
    <gazebo reference="base_link">
        <material>Gazebo/Orange</material>
        <turnGravityOff>True</turnGravityOff>
    </gazebo>
    <gazebo reference="link_1">
        <material>Gazebo/Orange</material>
        <turnGravityOff>True</turnGravityOff>
    </gazebo>
    <gazebo reference="link_2">
        <material>Gazebo/Orange</material>
        <turnGravityOff>True</turnGravityOff>
    </gazebo>
    <gazebo reference="link_3">
        <material>Gazebo/Orange</material>
        <turnGravityOff>True</turnGravityOff>
    </gazebo>
    <gazebo reference="link_4">
        <material>Gazebo/Orange</material>
        <turnGravityOff>True</turnGravityOff>
    </gazebo>
    <gazebo reference="link_5">
        <material>Gazebo/Orange</material>
        <turnGravityOff>True</turnGravityOff>
    </gazebo>
    <gazebo reference="link_6">
        <material>Gazebo/Black</material>
        <turnGravityOff>True</turnGravityOff>
    </gazebo>

    <!-- End gazebo specific link properties -->

    <gazebo>
        <plugin name="gazebo_ros_control" filename="libgazebo_ros_control.so">
            <robotNamespace>/</robotNamespace>
            <robotSimType>gazebo_ros_control/DefaultRobotHWSim</robotSimType>
        </plugin>
    </gazebo>
</robot>

